---
title: "linux下巡风项目运行错误排查"
date: 2017-03-05 11:56:17 +0800
img: /assets/images/201703/05-01.png

categories: 一个问题
tags: [ubuntu, mongodb, python, 问题集]
---

>最近看到了[同程安全](http://mp.weixin.qq.com/s/sFDY8vzonIW2gAcw0CCkzQ)的开源项目 - [巡风](https://github.com/ysrc/xunfeng), 感觉挺好玩的, 准备在自己的系统安装, 按照[官方教程](https://github.com/ysrc/xunfeng/blob/master/docs/install/Linux.md), 其中遇到一些问题

<mark>问题描述</mark>

> mongodb数据库连接不上
```bash
$ python2 Run.py
Traceback (most recent call last):
  File "Run.py", line 1, in <module>
    from views.View import app
  File "/path/to/xunfeng/views/__init__.py", line 12, in <module>
    app.config.get('DBUSERNAME'), app.config.get('DBPASSWORD'))
  File "/path/to/xunfeng/views/lib/Conn.py", line 13, in __init__
    self.coll.authenticate(username, password)
    ...
  File "/usr/local/lib/python2.7/dist-packages/pymongo/helpers.py", line 210, in _check_command_response
    raise OperationFailure(msg % errmsg, code, response)
pymongo.errors.OperationFailure: Authentication failed.
```

<mark>解决方法</mark>

修改mongo数据库 连接方式解决了 [^1] [^1.1]

![巡风](/assets/images/201703/05-01.png)

<mark>问题描述</mark>

> xlwt模块没有找到
```bash
$ python2 Run.py                                                          1 ↵
Traceback (most recent call last):
  File "Run.py", line 1, in <module>
    from views.View import app
  File "/path/to/xunfeng/views/View.py", line 10, in <module>
    from lib.CreateExcel import *
  File "/path/to/xunfeng/views/lib/CreateExcel.py", line 3, in <module>
    import xlwt
ImportError: No module named xlwt
```

<mark>解决方法</mark>

安装xlwt包 解决了.
```bash
$ sudo pip2 install xlwt
```

<mark>问题描述</mark>

>socket权限问题
```bash
$ python2 Run.py        
Traceback (most recent call last):
  File "Run.py", line 5, in <module>
    app.run(threaded=True, port=80,host='0.0.0.0')
  File "/usr/local/lib/python2.7/dist-packages/flask/app.py", line 841, in run
    run_simple(host, port, self, **options)
  File "/usr/local/lib/python2.7/dist-packages/werkzeug/serving.py", line 691, in run_simple
    s.bind((hostname, port))
  File "/usr/lib/python2.7/socket.py", line 228, in meth
    return getattr(self._sock,name)(*args)
socket.error: [Errno 13] Permission denied
```

<mark>解决方法</mark>

直接使用sudo权限 解决了 [^2]

<mark>问题描述</mark>

>端口被占用
```bash
$ sudo python2 Run.py                                                     1 ↵
Traceback (most recent call last):
  File "Run.py", line 5, in <module>
    app.run(threaded=True, port=80,host='0.0.0.0')
  File "/usr/local/lib/python2.7/dist-packages/flask/app.py", line 841, in run
    run_simple(host, port, self, **options)
  File "/usr/local/lib/python2.7/dist-packages/werkzeug/serving.py", line 699, in run_simple
    s.listen(LISTEN_QUEUE)
  File "/usr/lib/python2.7/socket.py", line 228, in meth
    return getattr(self._sock,name)(*args)
socket.error: [Errno 98] Address already in use
```

<mark>解决方法</mark>

将 run.py 的port 80 换成 800 即可. [^3]

```python
from views.View import app

if __name__ == '__main__':
    app.debug = True
    app.run(threaded=True, port=800,host='0.0.0.0')
```

处理完毕, 终于可以运行了.

```bash
$ sudo python2 Run.py
 * Running on http://0.0.0.0:800/ (Press CTRL+C to quit)
 * Restarting with stat
 * Debugger is active!
 * Debugger pin code: 290-209-200
```

![巡风](/assets/images/201703/05-02.png)

---
## 参考文档
- [pymongo auth failed in python script](http://stackoverflow.com/questions/40346767/pymongo-auth-failed-in-python-script)
- [README mongodb添加认证处少了db.auth('username','password')](https://github.com/ysrc/xunfeng/issues/56)
- [Permission denied when creating a fake email server](http://stackoverflow.com/questions/25709716/socket-error-errno-13-permission-denied-when-creating-a-fake-email-server)
- [Address already in use](http://stackoverflow.com/questions/4465959/python-errno-98-address-already-in-use)

[^1]: http://stackoverflow.com/questions/40346767/pymongo-auth-failed-in-python-script
[^1.1]: https://github.com/ysrc/xunfeng/issues/56
[^2]: http://stackoverflow.com/questions/25709716/socket-error-errno-13-permission-denied-when-creating-a-fake-email-server
[^3]: http://stackoverflow.com/questions/4465959/python-errno-98-address-already-in-use
